Workbook

Sheet modelos_APT_2025
C2: BANC | J2: Projeção
C3: 1 | D3: 2 | E3: 3 | F3: 4 | J3: 1 | K3: 2 | L3: 3 | M3: 4 | O3: Ano | P3: Cresc PIB Real | Q3: Desemprego | R3: Inflação | S3: Taxa de Juros Real | T3: Risco Pais (taxa real) | U3: Cresc PIB Real (IN) | V3: Inflação (IN) | W3: Taxa de Juros Real (IN) | X3: Premio de Risco | Y3: (d) Cresc PIB Real | Z3: (d) Desemprego | AA3: (d) Inflação | AB3: (d) Taxa de Juros Real | AC3: (d) Risco Pais (taxa real) | AD3: (d) Cresc PIB Real (IN) | AE3: (d) Inflação (IN) | AF3: (d) Taxa de Juros Real (IN) | AG3: (d) Premio de Risco | AH3: (lag) Cresc PIB Real | AI3: (lag) Desemprego | AJ3: (lag) Inflação | AK3: (lag) Taxa de Juros Real | AL3: (lag) Risco Pais (taxa real) | AM3: (lag) Cresc PIB Real (IN) | AN3: (lag) Inflação (IN) | AO3: (lag) Taxa de Juros Real (IN) | AP3: (lag) Premio de Risco | AQ3: (lag) (d) Cresc PIB Real | AR3: (lag) (d) Desemprego | AS3: (lag) (d) Inflação | AT3: (lag) (d) Taxa de Juros Real | AU3: (lag) (d) Risco Pais (taxa real) | AV3: (lag) (d) Cresc PIB Real (IN) | AW3: (lag) (d) Inflação (IN) | AX3: (lag) (d) Taxa de Juros Real (IN) | AY3: (lag) (d) Premio de Risco
B4: Fatores Usados | C4: Cresc PIB Real, (lag) Risco Pais (taxa real), (lag) (d) Desemprego | D4: Cresc PIB Real (IN), (d) Cresc PIB Real (IN), (lag) (d) Inflação | E4: Inflação, (d) Taxa de Juros Real (IN), (lag) (d) Premio de Risco | F4: Cresc PIB Real (IN), (lag) Inflação, (lag) (d) Premio de Risco | G4: . | H4: Ano | I4: R | J4: E | K4: E | L4: E | M4: E | O4: 0 | P4: 0.02 | Q4: 0.08 | R4: 0.02 | S4: 0.02 | T4: 0.028 | U4: 0.0205 | V4: 0.02 | W4: 0.02 | X4: 0.0264 | Y4: 0 | Z4: 0 | AA4: 0 | AB4: 0 | AC4: 0 | AD4: 0 | AE4: 0 | AF4: 0 | AG4: 0 | AH4: 0.02 | AI4: 0.08 | AJ4: 0.02 | AK4: 0.02 | AL4: 0.028 | AM4: 0.0205 | AN4: 0.02 | AO4: 0.02 | AP4: 0.0264 | AQ4: 0 | AR4: 0 | AS4: 0 | AT4: 0 | AU4: 0 | AV4: 0 | AW4: 0 | AX4: 0 | AY4: 0
B5: Var_signif | C5: 3 | D5: 3 | E5: 3 | F5: 3 | H5: 0 | I5: =retornos!B2 -> 0.0346 | J5: {=C10 + MMULT($P$4:$AY$4, IF(C11:C46="", 0, C11:C46))} -> 0.034361156 | K5: {=D10 + MMULT($P$4:$AY$4, IF(D11:D46="", 0, D11:D46))} -> 0.03423365 | L5: {=E10 + MMULT($P$4:$AY$4, IF(E11:E46="", 0, E11:E46))} -> 0.034950832 | M5: {=F10 + MMULT($P$4:$AY$4, IF(F11:F46="", 0, F11:F46))} -> 0.034317849 | O5: 1 | P5: 0.0202 | Q5: 0.0803 | R5: 0.0203 | S5: 0.02 | T5: 0.0286 | U5: 0.02 | V5: 0.0208 | W5: 0.0202 | X5: 0.0418 | Y5: 0.01 | Z5: 0.00375 | AA5: 0.015 | AB5: 0 | AC5: 0.021428571 | AD5: -0.024390244 | AE5: 0.04 | AF5: 0.01 | AG5: 0.58333333 | AH5: 0.02 | AI5: 0.08 | AJ5: 0.02 | AK5: 0.02 | AL5: 0.028 | AM5: 0.0205 | AN5: 0.02 | AO5: 0.02 | AP5: 0.0264 | AQ5: 0 | AR5: 0 | AS5: 0 | AT5: 0 | AU5: 0 | AV5: 0 | AW5: 0 | AX5: 0 | AY5: 0
B6: R2 Ajustado | C6: 0.99999425 | D6: 0.9999842 | E6: 0.99997945 | F6: 0.99997395 | H6: 1 | I6: =retornos!B3 -> 0.0353 | J6: {=C10 + MMULT($P$5:$AY$5, IF(C11:C46="", 0, C11:C46))} -> 0.035482946 | K6: {=D10 + MMULT($P$5:$AY$5, IF(D11:D46="", 0, D11:D46))} -> 0.035643836 | L6: {=E10 + MMULT($P$5:$AY$5, IF(E11:E46="", 0, E11:E46))} -> 0.034854984 | M6: {=F10 + MMULT($P$5:$AY$5, IF(F11:F46="", 0, F11:F46))} -> 0.035834261 | O6: 2 | P6: -0.0026 | Q6: 0.1063 | R6: 0.0499 | S6: 0.02 | T6: 0.0466 | U6: 0.0596 | V6: 0.0051 | W6: 0.0607 | X6: -0.0377 | Y6: -1.1287129 | Z6: 0.3237858 | AA6: 1.4581281 | AB6: 0 | AC6: 0.62937063 | AD6: 1.98 | AE6: -0.75480769 | AF6: 2.0049505 | AG6: -1.9019139 | AH6: 0.0202 | AI6: 0.0803 | AJ6: 0.0203 | AK6: 0.02 | AL6: 0.0286 | AM6: 0.02 | AN6: 0.0208 | AO6: 0.0202 | AP6: 0.0418 | AQ6: 0.01 | AR6: 0.00375 | AS6: 0.015 | AT6: 0 | AU6: 0.021428571 | AV6: -0.024390244 | AW6: 0.04 | AX6: 0.01 | AY6: 0.58333333
B7: SQR | C7: 9.2052805e-08 | D7: 2.528503e-07 | E7: 3.288101e-07 | F7: 4.1686883e-07 | H7: 2 | I7: =retornos!B4 -> -0.0906 | J7: {=C10 + MMULT($P$6:$AY$6, IF(C11:C46="", 0, C11:C46))} -> -0.090580202 | K7: {=D10 + MMULT($P$6:$AY$6, IF(D11:D46="", 0, D11:D46))} -> -0.090591396 | L7: {=E10 + MMULT($P$6:$AY$6, IF(E11:E46="", 0, E11:E46))} -> -0.09057395 | M7: {=F10 + MMULT($P$6:$AY$6, IF(F11:F46="", 0, F11:F46))} -> -0.090666955 | O7: 3 | P7: 0.0397 | Q7: 0.088 | R7: 0.0336 | S7: 0.02 | T7: 0.0474 | U7: 0.0396 | V7: 0.0009 | W7: 0.0404 | X7: 0.1355 | Y7: -16.269231 | Z7: -0.17215428 | AA7: -0.32665331 | AB7: 0 | AC7: 0.017167382 | AD7: -0.33557047 | AE7: -0.82352941 | AF7: -0.33443163 | AG7: -4.5941645 | AH7: -0.0026 | AI7: 0.1063 | AJ7: 0.0499 | AK7: 0.02 | AL7: 0.0466 | AM7: 0.0596 | AN7: 0.0051 | AO7: 0.0607 | AP7: -0.0377 | AQ7: -1.1287129 | AR7: 0.3237858 | AS7: 1.4581281 | AT7: 0 | AU7: 0.62937063 | AV7: 1.98 | AW7: -0.75480769 | AX7: 2.0049505 | AY7: -1.9019139
B8: BIC | C8: -83.761677 | D8: -77.699066 | E8: -76.122969 | F8: -74.699222 | H8: 3 | I8: =retornos!B5 -> 0.1444 | J8: {=C10 + MMULT($P$7:$AY$7, IF(C11:C46="", 0, C11:C46))} -> 0.14439672 | K8: {=D10 + MMULT($P$7:$AY$7, IF(D11:D46="", 0, D11:D46))} -> 0.14440187 | L8: {=E10 + MMULT($P$7:$AY$7, IF(E11:E46="", 0, E11:E46))} -> 0.14438109 | M8: {=F10 + MMULT($P$7:$AY$7, IF(F11:F46="", 0, F11:F46))} -> 0.14443897 | O8: 4 | P8: 0.0156 | Q8: 0.0935 | R8: 0.0247 | S8: 0.02 | T8: 0.0258 | U8: 0.0244 | V8: 0.0104 | W8: 0.0307 | X8: 0.0938 | Y8: -0.6070529 | Z8: 0.0625 | AA8: -0.26488095 | AB8: 0 | AC8: -0.4556962 | AD8: -0.38383838 | AE8: 10.555556 | AF8: -0.24009901 | AG8: -0.30774908 | AH8: 0.0397 | AI8: 0.088 | AJ8: 0.0336 | AK8: 0.02 | AL8: 0.0474 | AM8: 0.0396 | AN8: 0.0009 | AO8: 0.0404 | AP8: 0.1355 | AQ8: -16.269231 | AR8: -0.17215428 | AS8: -0.32665331 | AT8: 0 | AU8: 0.017167382 | AV8: -0.33557047 | AW8: -0.82352941 | AX8: -0.33443163 | AY8: -4.5941645
B9: pv(F) | C9: 3.4519533e-06 | D9: 9.4818028e-06 | E9: 1.2330265e-05 | F9: 1.5632428e-05 | H9: 4 | I9: =retornos!B6 -> 0.149 | J9: {=C10 + MMULT($P$8:$AY$8, IF(C11:C46="", 0, C11:C46))} -> 0.14900628 | K9: {=D10 + MMULT($P$8:$AY$8, IF(D11:D46="", 0, D11:D46))} -> 0.14899452 | L9: {=E10 + MMULT($P$8:$AY$8, IF(E11:E46="", 0, E11:E46))} -> 0.14900569 | M9: {=F10 + MMULT($P$8:$AY$8, IF(F11:F46="", 0, F11:F46))} -> 0.14898969 | O9: 5 | P9: 0.0352 | Q9: 0.0778 | R9: 0.0149 | S9: 0.02 | T9: 0.0188 | U9: 0.0103 | V9: 0.0169 | W9: 0.0108 | X9: 0.1021 | Y9: 1.2564103 | Z9: -0.16791444 | AA9: -0.39676113 | AB9: 0 | AC9: -0.27131783 | AD9: -0.57786885 | AE9: 0.625 | AF9: -0.64820847 | AG9: 0.088486141 | AH9: 0.0156 | AI9: 0.0935 | AJ9: 0.0247 | AK9: 0.02 | AL9: 0.0258 | AM9: 0.0244 | AN9: 0.0104 | AO9: 0.0307 | AP9: 0.0938 | AQ9: -0.6070529 | AR9: 0.0625 | AS9: -0.26488095 | AT9: 0 | AU9: -0.4556962 | AV9: -0.38383838 | AW9: 10.555556 | AX9: -0.24009901 | AY9: -0.30774908
B10: const | C10: -0.21077434 | D10: -0.097356614 | E10: -0.029159899 | F10: 0.0011631977 | H10: 5 | I10: =retornos!B7 -> 0.092 | J10: {=C10 + MMULT($P$9:$AY$9, IF(C11:C46="", 0, C11:C46))} -> 0.092033095 | K10: {=D10 + MMULT($P$9:$AY$9, IF(D11:D46="", 0, D11:D46))} -> 0.092017526 | L10: {=E10 + MMULT($P$9:$AY$9, IF(E11:E46="", 0, E11:E46))} -> 0.092081358 | M10: {=F10 + MMULT($P$9:$AY$9, IF(F11:F46="", 0, F11:F46))} -> 0.091786185 | O10: 6 | P10: 0.0267 | Q10: 0.07 | R10: 0.0289 | S10: 0.02 | T10: 0.0282 | U10: 0.0143 | V10: 0.0186 | W10: 0.0146 | X10: -0.02 | Y10: -0.24147727 | Z10: -0.10025707 | AA10: 0.93959732 | AB10: 0 | AC10: 0.5 | AD10: 0.38834951 | AE10: 0.10059172 | AF10: 0.35185185 | AG10: -1.1958864 | AH10: 0.0352 | AI10: 0.0778 | AJ10: 0.0149 | AK10: 0.02 | AL10: 0.0188 | AM10: 0.0103 | AN10: 0.0169 | AO10: 0.0108 | AP10: 0.1021 | AQ10: 1.2564103 | AR10: -0.16791444 | AS10: -0.39676113 | AT10: 0 | AU10: -0.27131783 | AV10: -0.57786885 | AW10: 0.625 | AX10: -0.64820847 | AY10: 0.088486141
B11: Cresc PIB Real | C11: 5.6089461 | H11: 6 | I11: =retornos!B8 -> 0 | J11: {=C10 + MMULT($P$10:$AY$10, IF(C11:C46="", 0, C11:C46))} -> 0.074297376 | K11: {=D10 + MMULT($P$10:$AY$10, IF(D11:D46="", 0, D11:D46))} -> -0.058442347 | L11: {=E10 + MMULT($P$10:$AY$10, IF(E11:E46="", 0, E11:E46))} -> 0.024853908 | M11: {=F10 + MMULT($P$10:$AY$10, IF(F11:F46="", 0, F11:F46))} -> 0.027624899
B12: Desemprego
B13: Inflacao | E13: 3.2055366
B14: Taxa de Juros Real
B15: Risco Pai­s (taxa real)
B16: Cresc PIB Real (IN) | D16: 6.4190373 | F16: -3.0328237
B17: Inflacao (IN)
B18: Taxa de Juros Real (IN)
B19: Premio de Risco
B20: (d) Cresc PIB Real
B21: (d) Desemprego
B22: (d) Inflacao
B23: (d) Taxa de Juros Real
B24: (d) Risco Pai­s (taxa real)
B25: (d) Cresc PIB Real (IN) | D25: -0.18940789
B26: (d) Inflacao (IN)
B27: (d) Taxa de Juros Real (IN) | E27: -0.10575093
B28: (d) Premio de Risco
B29: (lag) Cresc PIB Real
B30: (lag) Desemprego
B31: (lag) Inflacao | F31: 4.7663769
B32: (lag) Taxa de Juros Real
B33: (lag) Risco Pai­s (taxa real) | C33: 4.7484492
B34: (lag) Cresc PIB Real (IN)
B35: (lag) Inflacao (IN)
B36: (lag) Taxa de Juros Real (IN)
B37: (lag) Premio de Risco
B38: (lag) (d) Cresc PIB Real
B39: (lag) (d) Desemprego | C39: -0.27419925
B40: (lag) (d) Inflacao | D40: -0.052118256
B41: (lag) (d) Taxa de Juros Real
...

Sheet fatores
A1: Ano | B1: Cresc PIB Real | C1: Desemprego | D1: Inflação | E1: Taxa de Juros Real | F1: Risco Pais (taxa real) | G1: Cresc PIB Real (IN) | H1: Inflação (IN) | I1: Taxa de Juros Real (IN) | J1: Premio de Risco | K1: ="(d) " & B1 -> (d) Cresc PIB Real | L1: ="(d) " & C1 -> (d) Desemprego | M1: ="(d) " & D1 -> (d) Inflação | N1: ="(d) " & E1 -> (d) Taxa de Juros Real | O1: ="(d) " & F1 -> (d) Risco Pais (taxa real) | P1: ="(d) " & G1 -> (d) Cresc PIB Real (IN) | Q1: ="(d) " & H1 -> (d) Inflação (IN) | R1: ="(d) " & I1 -> (d) Taxa de Juros Real (IN) | S1: ="(d) " & J1 -> (d) Premio de Risco | T1: ="(lag) " & B1 -> (lag) Cresc PIB Real | U1: ="(lag) " & C1 -> (lag) Desemprego | V1: ="(lag) " & D1 -> (lag) Inflação | W1: ="(lag) " & E1 -> (lag) Taxa de Juros Real | X1: ="(lag) " & F1 -> (lag) Risco Pais (taxa real) | Y1: ="(lag) " & G1 -> (lag) Cresc PIB Real (IN) | Z1: ="(lag) " & H1 -> (lag) Inflação (IN) | AA1: ="(lag) " & I1 -> (lag) Taxa de Juros Real (IN) | ... AK1: ="(lag) " & S1 -> (lag) (d) Premio de Risco
A2: 0 | B2: 0.02 | C2: 0.08 | D2: 0.02 | E2: 0.02 | F2: 0.028 | G2: 0.0205 | H2: 0.02 | I2: 0.02 | J2: =retornos!K2 - 2% -> 0.0264 | K2: 0 | L2: 0 | M2: 0 | N2: 0 | O2: 0 | P2: 0 | Q2: 0 | R2: 0 | S2: 0 | T2: =B2 -> 0.02 | U2: =C2 -> 0.08 | V2: =D2 -> 0.02 | W2: =E2 -> 0.02 | X2: =F2 -> 0.028 | Y2: =G2 -> 0.0205 | Z2: =H2 -> 0.02 | AA2: =I2 -> 0.02 | ... AK2: =S2 -> 0
A3: 1 | B3: 0.0202 | C3: 0.0803 | D3: 0.0203 | E3: 0.02 | F3: 0.0286 | G3: 0.02 | H3: 0.0208 | I3: 0.0202 | J3: =retornos!K3 - 2% -> 0.0418 | K3: =B3/B2 - 1 -> 0.01 | L3: =C3/C2 - 1 -> 0.00375 | M3: =D3/D2 - 1 -> 0.015 | N3: =E3/E2 - 1 -> 0 | O3: =F3/F2 - 1 -> 0.021428571 | P3: =G3/G2 - 1 -> -0.024390244 | Q3: =H3/H2 - 1 -> 0.04 | R3: =I3/I2 - 1 -> 0.01 | S3: =J3/J2 - 1 -> 0.58333333 | T3: =B2 -> 0.02 | U3: =C2 -> 0.08 | V3: =D2 -> 0.02 | W3: =E2 -> 0.02 | X3: =F2 -> 0.028 | Y3: =G2 -> 0.0205 | Z3: =H2 -> 0.02 | AA3: =I2 -> 0.02 | ... AK3: =S2 -> 0
A4: 2 | B4: -0.0026 | C4: 0.1063 | D4: 0.0499 | E4: 0.02 | F4: 0.0466 | G4: 0.0596 | H4: 0.0051 | I4: 0.0607 | J4: =retornos!K4 - 2% -> -0.0377 | K4: =B4/B3 - 1 -> -1.1287129 | L4: =C4/C3 - 1 -> 0.3237858 | M4: =D4/D3 - 1 -> 1.4581281 | N4: =E4/E3 - 1 -> 0 | O4: =F4/F3 - 1 -> 0.62937063 | P4: =G4/G3 - 1 -> 1.98 | Q4: =H4/H3 - 1 -> -0.75480769 | R4: =I4/I3 - 1 -> 2.0049505 | S4: =J4/J3 - 1 -> -1.9019139 | T4: =B3 -> 0.0202 | U4: =C3 -> 0.0803 | V4: =D3 -> 0.0203 | W4: =E3 -> 0.02 | X4: =F3 -> 0.0286 | Y4: =G3 -> 0.02 | Z4: =H3 -> 0.0208 | AA4: =I3 -> 0.0202 | ... AK4: =S3 -> 0.58333333
A5: 3 | B5: 0.0397 | C5: 0.088 | D5: 0.0336 | E5: 0.02 | F5: 0.0474 | G5: 0.0396 | H5: 0.0009 | I5: 0.0404 | J5: =retornos!K5 - 2% -> 0.1355 | K5: =B5/B4 - 1 -> -16.269231 | L5: =C5/C4 - 1 -> -0.17215428 | M5: =D5/D4 - 1 -> -0.32665331 | N5: =E5/E4 - 1 -> 0 | O5: =F5/F4 - 1 -> 0.017167382 | P5: =G5/G4 - 1 -> -0.33557047 | Q5: =H5/H4 - 1 -> -0.82352941 | R5: =I5/I4 - 1 -> -0.33443163 | S5: =J5/J4 - 1 -> -4.5941645 | T5: =B4 -> -0.0026 | U5: =C4 -> 0.1063 | V5: =D4 -> 0.0499 | W5: =E4 -> 0.02 | X5: =F4 -> 0.0466 | Y5: =G4 -> 0.0596 | Z5: =H4 -> 0.0051 | AA5: =I4 -> 0.0607 | ... AK5: =S4 -> -1.9019139
A6: 4 | B6: 0.0156 | C6: 0.0935 | D6: 0.0247 | E6: 0.02 | F6: 0.0258 | G6: 0.0244 | H6: 0.0104 | I6: 0.0307 | J6: =retornos!K6 - 2% -> 0.0938 | K6: =B6/B5 - 1 -> -0.6070529 | L6: =C6/C5 - 1 -> 0.0625 | M6: =D6/D5 - 1 -> -0.26488095 | N6: =E6/E5 - 1 -> 0 | O6: =F6/F5 - 1 -> -0.4556962 | P6: =G6/G5 - 1 -> -0.38383838 | Q6: =H6/H5 - 1 -> 10.555556 | R6: =I6/I5 - 1 -> -0.24009901 | S6: =J6/J5 - 1 -> -0.30774908 | T6: =B5 -> 0.0397 | U6: =C5 -> 0.088 | V6: =D5 -> 0.0336 | W6: =E5 -> 0.02 | X6: =F5 -> 0.0474 | Y6: =G5 -> 0.0396 | Z6: =H5 -> 0.0009 | AA6: =I5 -> 0.0404 | ... AK6: =S5 -> -4.5941645
A7: 5 | B7: 0.0352 | C7: 0.0778 | D7: 0.0149 | E7: 0.02 | F7: 0.0188 | G7: 0.0103 | H7: 0.0169 | I7: 0.0108 | J7: =retornos!K7 - 2% -> 0.1021 | K7: =B7/B6 - 1 -> 1.2564103 | L7: =C7/C6 - 1 -> -0.16791444 | M7: =D7/D6 - 1 -> -0.39676113 | N7: =E7/E6 - 1 -> 0 | O7: =F7/F6 - 1 -> -0.27131783 | P7: =G7/G6 - 1 -> -0.57786885 | Q7: =H7/H6 - 1 -> 0.625 | R7: =I7/I6 - 1 -> -0.64820847 | S7: =J7/J6 - 1 -> 0.088486141 | T7: =B6 -> 0.0156 | U7: =C6 -> 0.0935 | V7: =D6 -> 0.0247 | W7: =E6 -> 0.02 | X7: =F6 -> 0.0258 | Y7: =G6 -> 0.0244 | Z7: =H6 -> 0.0104 | AA7: =I6 -> 0.0307 | ... AK7: =S6 -> -0.30774908

Sheet retornos
A1: Ano | B1: BANC | C1: LMAG | D1: DRWH | E1: SAUD | F1: SMAQ | G1: PETN | H1: MM | I1: Renda Fixa - CP | J1: Renda Fixa - LP | K1: Índice Bolsa EW (pontos) | L1: ETF Ouro | M1: Dolar Futuro (Comprado) | N1: Dolar Futuro (Vendido)
A2: 0 | B2: 0.0346 | C2: 0.0452 | D2: 0.0472 | E2: 0.0441 | F2: 0.0335 | G2: 0.0502 | H2: 0.0406 | I2: 0.0298 | J2: 0.0311 | K2: 0.0464 | L2: 0.0319 | M2: -0.0039 | N2: 0.0039
A3: 1 | B3: 0.0353 | C3: 0.0909 | D3: 0.0838 | E3: -0.0134 | F3: 0.1087 | G3: 0.1243 | H3: -0.0265 | I3: 0.0286 | J3: 0.029 | K3: 0.0618 | L3: 0.0209 | M3: -0.0154 | N3: 0.0154
A4: 2 | B4: -0.0906 | C4: -0.0911 | D4: -0.0533 | E4: -0.0452 | F4: -0.1491 | G4: 0.1186 | H4: 0.1365 | I4: 0.0466 | J4: 0.0266 | K4: -0.0177 | L4: 0.235 | M4: 0.4881 | N4: -0.4881
A5: 3 | B5: 0.1444 | C5: 0.1223 | D5: 0.0176 | E5: 0.2251 | F5: 0.166 | G5: 0.0192 | H5: 0.3294 | I5: 0.0474 | J5: 0.0474 | K5: 0.1555 | L5: 0.0959 | M5: 0.1738 | N5: -0.1738
A6: 4 | B6: 0.149 | C6: 0.0484 | D6: -0.0486 | E6: -0.0713 | F6: 0.2036 | G6: 0.2084 | H6: 0.2631 | I6: 0.0258 | J6: 0.0522 | K6: 0.1138 | L6: 0.0113 | M6: -0.0743 | N6: 0.0743
A7: 5 | B7: 0.092 | C7: 0.1567 | D7: 0.1595 | E7: 0.1608 | F7: -0.0264 | G7: 0.1363 | H7: 0.1216 | I7: 0.0188 | J7: 0.0301 | K7: 0.1221 | L7: 0.1851 | M7: -0.3275 | N7: 0.3275

Sheet precos
A1: Ano | B1: Dia Útil | C1: BANC | D1: LMAG | E1: DRWH | F1: SAUD | G1: SMAQ | H1: PETN | I1: MM | J1: Renda Fixa - CP | K1: Renda Fixa - LP | L1: Dólar | M1: Índice Bolsa EW (pontos) | N1: OURO10 | O1: Valor do Contrato Futuro em $ (Posição Comprada) | P1: Valor do Contrato Futuro em $ (Posição Vendida)
A2: -1 | B2: 252 | C2: 12.5 | D2: 5.76 | E2: 27.13 | F2: 20.93 | G2: 17.84 | H2: 47.5 | I2: 34.02 | J2: 970.08211 | K2: 937.22506 | L2: 5 | M2: 100 | N2: 50 | O2: 1000 | P2: 1000
A3: 0 | B3: 1 | C3: 12.543153 | D3: 5.7298009 | E3: 27.348136 | F3: 21.089118 | G3: 18.006221 | H3: 47.62733 | I3: 34.381254 | J3: 978.15444 | K3: 940.18499 | L3: 4.9309538 | M3: 100.17092 | N3: 49.317609 | O3: 986.19076 | P3: 1013.8092
A4: 0 | B4: 2 | C4: 12.50122 | D4: 5.7193481 | E4: 27.34841 | F4: 21.087027 | G4: 18.06893 | H4: 47.508703 | I4: 34.698311 | J4: 969.77725 | K4: 936.95057 | L4: 4.9539945 | M4: 100.53888 | N4: 49.744297 | O4: 990.79889 | P4: 1009.2011
A5: 0 | B5: 3 | C5: 12.48091 | D5: 5.714449 | E5: 26.998288 | F5: 21.139687 | G5: 18.073672 | H5: 47.068242 | I5: 35.425973 | J5: 977.56016 | K5: 936.99274 | L5: 4.939391 | M5: 100.14546 | N5: 49.564565 | O5: 987.8782 | P5: 1012.1218
A6: 0 | B6: 4 | C6: 12.487836 | D6: 5.7157081 | E6: 27.012045 | F6: 20.96386 | G6: 17.981884 | H6: 46.49324 | I6: 35.140741 | J6: 970.94733 | K6: 935.74026 | L6: 4.9112194 | M6: 100.01299 | N6: 48.611151 | O6: 982.24387 | P6: 1017.7561
A7: 0 | B7: 5 | C7: 12.571878 | D7: 5.6991705 | E7: 27.112575 | F7: 20.959464 | G7: 17.954305 | H7: 46.587583 | I7: 34.941408 | J7: 978.19176 | K7: 933.42446 | L7: 4.8618125 | M7: 99.704742 | N7: 48.618132 | O7: 972.3625 | P7: 1027.6375
A8: 0 | B8: 6 | C8: 12.64648 | D8: 5.6851763 | E8: 27.0361 | F8: 20.953934 | G8: 17.907745 | H8: 46.543042 | I8: 35.289725 | J8: 971.51096 | K8: 930.23443 | L8: 4.8598835 | M8: 99.385097 | N8: 49.21342 | O8: 971.9767 | P8: 1028.0233
A9: 0 | B9: 7 | C9: 12.615741 | D9: 5.7109665 | E9: 27.058617 | F9: 20.827402 | G9: 17.829823 | H9: 46.046878 | I9: 35.309443 | J9: 978.66199 | K9: 937.06732 | L9: 4.8187237 | M9: 99.120415 | N9: 49.838099 | O9: 963.74474 | P9: 1036.2553
A10: 0 | B10: 8 | C10: 12.591319 | D10: 5.7283332 | E10: 26.9001 | F10: 20.854913 | G10: 17.955932 | H10: 46.040246 | I10: 35.079456 | J10: 972.07443 | K10: 937.64278 | L10: 4.7851968 | M10: 99.167361 | N10: 50.281191 | O10: 957.03937 | P10: 1042.9606
A11: 0 | B11: 9 | C11: 12.630681 | D11: 5.708781 | E11: 26.71362 | F11: 20.599481 | G11: 17.76075 | H11: 45.901426 | I11: 34.621441 | J11: 979.32273 | K11: 937.61977 | L11: 4.7840856 | M11: 98.701683 | N11: 49.927755 | O11: 956.81711 | P11: 1043.1829
A12: 0 | B12: 10 | C12: 12.554492 | D12: 5.6667905 | E12: 26.71169 | F12: 20.72272 | G12: 17.656003 | H12: 45.69166 | I12: 34.026112 | J12: 973.81852 | K12: 933.43327 | L12: 4.7874186 | M12: 98.441244 | N12: 49.850898 | O12: 957.48371 | P12: 1042.5163
A13: 0 | B13: 11 | C13: 12.587316 | D13: 5.7473743 | E13: 26.941041 | F13: 20.849139 | G13: 17.571473 | H13: 46.223416 | I13: 33.997568 | J13: 978.22599 | K13: 939.4223 | L13: 4.7771392 | M13: 98.954466 | N13: 49.940829 | O13: 955.42783 | P13: 1044.5722
... A1514: 5 | B1514: 252 | C1514: 17.48448 | D1514: 8.1251267 | E1514: 32.723661 | F1514: 27.187225 | G1514: 23.764671 | H1514: 87.794786 | I1514: 73.766943 | J1514: 998.77309 | K1514: 968.2508 | L1514: 5.2078496 | M1514: 148.3896 | N1514: 1654.7134 | O1514: 934.50107 | P1514: 1065.4989

Sheet correlacao_fatores
A1: Ativos | B1: Cresc PIB Real | C1: Taxa de Juros Real (IN) | D1: Desemprego | E1: Inflação | F1: Taxa de Juros Real | G1: Risco Pais (taxa real) | H1: Cresc PIB Real (IN) | I1: Inflação (IN) | J1: Premio de Risco | K1: (d) Cresc PIB Real | L1: (d) Desemprego | M1: (d) Inflação | N1: (d) Taxa de Juros Real | O1: (d) Risco Pais (taxa real) | P1: (d) Cresc PIB Real (IN) | Q1: (d) Inflação (IN) | R1: (d) Taxa de Juros Real (IN) | S1: (d) Premio de Risco
A2: LMAG | B2: 0.83233628 | C2: -0.4952068 | D2: -0.56922331 | E2: -0.43380387 | F2: -0.20806002 | G2: -0.27402601 | H2: -0.40930268 | I2: -0.19607797 | J2: 0.080608838 | K2: -0.28944072 | L2: -0.80588717 | M2: -0.57470759 | N2: -0.31107186 | O2: -0.39989985 | P2: -0.37215392 | Q2: -0.12493863 | R2: -0.76071397 | S2: 0.36435812
A3: Índice Bolsa EW (pontos) | B3: 0.81635833 | C3: 0.057177671 | D3: -0.27290848 | E3: -0.2824119 | F3: -0.043204686 | G3: -0.25620087 | H3: -0.27789637 | I3: -0.29115998 | J3: 0.69010761 | K3: -0.61039256 | L3: -0.77009963 | M3: -0.74290151 | N3: -0.61977527 | O3: -0.6809544 | P3: 0.23743182 | Q3: -0.5766037 | R3: -0.6089165 | S3: 0.64051983
A4: SAUD | B4: 0.69421102 | C4: -0.33049137 | D4: -0.23632414 | E4: 0.04432511 | F4: 0.34067301 | G4: 0.22589716 | H4: -0.82135185 | I4: 0.31599496 | J4: 0.19127742 | K4: -0.65206413 | L4: -0.60309228 | M4: -0.23875419 | N4: 0.13000206 | O4: -0.077839867 | P4: -0.62213355 | Q4: 0.10881306 | R4: -0.48762576 | S4: 0.6693973
A5: Renda Fixa - CP | B5: 0.55191836 | C5: -0.087180447 | D5: -0.14757908 | E5: 0.066924953 | F5: 0.49872006 | G5: 0.060558325 | H5: -0.3171243 | I5: 0.10318591 | J5: 0.83894062 | K5: -0.90358084 | L5: -0.4826931 | M5: -0.38860685 | N5: -0.086383661 | O5: -0.45303213 | P5: -0.12809488 | Q5: -0.54691452 | R5: -0.37056787 | S5: 0.93751691
A6: BANC | B6: 0.51623339 | C6: 0.44524217 | D6: 0.048342504 | E6: -0.083980389 | F6: 0.028232602 | G6: -0.1437085 | H6: -0.13056033 | I6: -0.2524103 | J6: 0.78291952 | K6: -0.54433012 | L6: -0.47109541 | M6: -0.58113535 | N6: -0.62596281 | O6: -0.58819024 | P6: 0.58141549 | Q6: -0.59719329 | R6: -0.28158128 | S6: 0.52770847
A7: MM | B7: 0.49522262 | C7: 0.46781262 | D7: 0.14264413 | E7: 0.081463839 | F7: 0.24046269 | G7: 0.036449263 | H7: -0.29991843 | I7: -0.059214027 | J7: 0.83115546 | K7: -0.70156859 | L7: -0.42470516 | M7: -0.47123488 | N7: -0.45507605 | O7: -0.48063486 | P7: 0.45115189 | Q7: -0.51683368 | R7: -0.21129061 | S7: 0.66881442
A8: Renda Fixa - LP | B8: 0.37161134 | C8: 0.47734006 | D8: 0.067075658 | E8: -0.085909121 | F8: 0.046338223 | G8: -0.21126602 | H8: 0.11559855 | I8: -0.32717129 | J8: 0.88666269 | K8: -0.52266921 | L8: -0.34821494 | M8: -0.56015854 | N8: -0.64139145 | O8: -0.65229611 | P8: 0.71170306 | Q8: -0.76797019 | R8: -0.19110988 | S8: 0.51159264
A9: DRWH | B9: 0.30148201 | C9: -0.73170304 | D9: -0.52798848 | E9: -0.37046704 | F9: -0.34840241 | G9: -0.17546138 | H9: -0.22656617 | I9: -0.043967152 | J9: -0.67378492 | K9: 0.32294665 | L9: -0.32507755 | M9: -0.057704798 | N9: 0.13853549 | O9: 0.13285102 | P9: -0.69982323 | Q9: 0.42379 | R9: -0.43256972 | S9: -0.25544633
A10: SMAQ | B10: 0.092883322 | C10: 0.49494971 | D10: 0.21024011 | E10: 0.097449451 | F10: 0.22979885 | G10: -0.072594619 | H10: 0.21991165 | I10: -0.16960188 | J10: 0.88650322 | K10: -0.49276722 | L10: -0.069206119 | M10: -0.30467226 | N10: -0.38474516 | O10: -0.47299392 | P10: 0.64862473 | Q10: -0.69196163 | R10: 0.040128706 | S10: 0.48481394
A11: Dolar Futuro (Vendido) | B11: 0.07284325 | C11: -0.22121364 | D11: -0.33755815 | E11: -0.52577168 | F11: -0.78251735 | G11: -0.45760924 | H11: 0.26624504 | I11: -0.47258096 | J11: -0.64364184 | K11: 0.71594872 | L11: -0.15084942 | M11: -0.19838214 | N11: -0.37133011 | O11: -0.057426837 | P11: 0.10243514 | Q11: 0.18195674 | R11: -0.23434555 | S11: -0.69002038
A12: PETN | B12: -0.068491748 | C12: 0.22957063 | D12: -0.12491208 | E12: -0.48171591 | F12: -0.72744356 | G12: -0.59660608 | H12: 0.69803672 | I12: -0.70799709 | J12: -0.044698141 | K12: 0.55912272 | L12: -0.021840531 | M12: -0.35795282 | N12: -0.70062453 | O12: -0.39353088 | P12: 0.77047176 | Q12: -0.37298672 | R12: -0.065605977 | S12: -0.53965216
A13: Dolar Futuro (Comprado) | B13: -0.07284325 | C13: 0.22121364 | D13: 0.33755815 | E13: 0.52577168 | F13: 0.78251735 | G13: 0.45760924 | H13: -0.26624504 | I13: 0.47258096 | J13: 0.64364184 | K13: -0.71594872 | L13: 0.15084942 | M13: 0.19838214 | N13: 0.37133011 | O13: 0.057426837 | P13: -0.10243514 | Q13: -0.18195674 | R13: 0.23434555 | S13: 0.69002038
A14: ETF Ouro | B14: -0.2026202 | C14: 0.17253491 | D14: 0.44231043 | E14: 0.54221359 | F14: 0.36981078 | G14: 0.6808847 | H14: -0.74586038 | I14: 0.69267081 | J14: -0.45971395 | K14: 0.0060093354 | L14: 0.28538679 | M14: 0.57582103 | N14: 0.61397903 | O14: 0.73589049 | P14: -0.46862851 | Q14: 0.87099308 | R14: 0.35697678 | S14: -0.087791401

Sheet Planilha1
A1: Coluna1 | B1: SMAQ | C1: LMAG | D1: Índice Bolsa EW (pontos) | E1: SAUD | F1: Renda Fixa - CP | G1: BANC | H1: MM | I1: Renda Fixa - LP | J1: DRWH | K1: Dolar Futuro (Vendido) | L1: PETN | M1: Dolar Futuro (Comprado) | N1: ETF Ouro
A2: Premio de Risco | B2: 0.88650322 | C2: 0.080608838 | D2: 0.69010761 | E2: 0.19127742 | F2: 0.83894062 | G2: 0.78291952 | H2: 0.83115546 | I2: 0.88666269 | J2: -0.67378492 | K2: -0.64364184 | L2: -0.044698141 | M2: 0.64364184 | N2: -0.45971395
A3: (d) Cresc PIB Real (IN) | B3: 0.64862473 | C3: -0.37215392 | D3: 0.23743182 | E3: -0.62213355 | F3: -0.12809488 | G3: 0.58141549 | H3: 0.45115189 | I3: 0.71170306 | J3: -0.69982323 | K3: 0.10243514 | L3: 0.77047176 | M3: -0.10243514 | N3: -0.46862851
A4: Taxa de Juros Real (IN) | B4: 0.49494971 | C4: -0.4952068 | D4: 0.057177671 | E4: -0.33049137 | F4: -0.087180447 | G4: 0.44524217 | H4: 0.46781262 | I4: 0.47734006 | J4: -0.73170304 | K4: -0.22121364 | L4: 0.22957063 | M4: 0.22121364 | N4: 0.17253491
A5: (d) Premio de Risco | B5: 0.48481394 | C5: 0.36435812 | D5: 0.64051983 | E5: 0.6693973 | F5: 0.93751691 | G5: 0.52770847 | H5: 0.66881442 | I5: 0.51159264 | J5: -0.25544633 | K5: -0.69002038 | L5: -0.53965216 | M5: 0.69002038 | N5: -0.087791401
A6: Taxa de Juros Real | B6: 0.22979885 | C6: -0.20806002 | D6: -0.043204686 | E6: 0.34067301 | F6: 0.49872006 | G6: 0.028232602 | H6: 0.24046269 | I6: 0.046338223 | J6: -0.34840241 | K6: -0.78251735 | L6: -0.72744356 | M6: 0.78251735 | N6: 0.36981078
A7: Cresc PIB Real (IN) | B7: 0.21991165 | C7: -0.40930268 | D7: -0.27789637 | E7: -0.82135185 | F7: -0.3171243 | G7: -0.13056033 | H7: -0.29991843 | I7: 0.11559855 | J7: -0.22656617 | K7: 0.26624504 | L7: 0.69803672 | M7: -0.26624504 | N7: -0.74586038
A8: Desemprego | B8: 0.21024011 | C8: -0.56922331 | D8: -0.27290848 | E8: -0.23632414 | F8: -0.14757908 | G8: 0.048342504 | H8: 0.14264413 | I8: 0.067075658 | J8: -0.52798848 | K8: -0.33755815 | L8: -0.12491208 | M8: 0.33755815 | N8: 0.44231043
A9: Inflação | B9: 0.097449451 | C9: -0.43380387 | D9: -0.2824119 | E9: 0.04432511 | F9: 0.066924953 | G9: -0.083980389 | H9: 0.081463839 | I9: -0.085909121 | J9: -0.37046704 | K9: -0.52577168 | L9: -0.48171591 | M9: 0.52577168 | N9: 0.54221359
A10: Cresc PIB Real | B10: 0.092883322 | C10: 0.83233628 | D10: 0.81635833 | E10: 0.69421102 | F10: 0.55191836 | G10: 0.51623339 | H10: 0.49522262 | I10: 0.37161134 | J10: 0.30148201 | K10: 0.07284325 | L10: -0.068491748 | M10: -0.07284325 | N10: -0.2026202
A11: (d) Taxa de Juros Real (IN) | B11: 0.040128706 | C11: -0.76071397 | D11: -0.6089165 | E11: -0.48762576 | F11: -0.37056787 | G11: -0.28158128 | H11: -0.21129061 | I11: -0.19110988 | J11: -0.43256972 | K11: -0.23434555 | L11: -0.065605977 | M11: 0.23434555 | N11: 0.35697678
A12: (d) Desemprego | B12: -0.069206119 | C12: -0.80588717 | D12: -0.77009963 | E12: -0.60309228 | F12: -0.4826931 | G12: -0.47109541 | H12: -0.42470516 | I12: -0.34821494 | J12: -0.32507755 | K12: -0.15084942 | L12: -0.021840531 | M12: 0.15084942 | N12: 0.28538679
A13: Risco Pais (taxa real) | B13: -0.072594619 | C13: -0.27402601 | D13: -0.25620087 | E13: 0.22589716 | F13: 0.060558325 | G13: -0.1437085 | H13: 0.036449263 | I13: -0.21126602 | J13: -0.17546138 | K13: -0.45760924 | L13: -0.59660608 | M13: 0.45760924 | N13: 0.6808847
... A19: (d) Inflação (IN) | B19: -0.69196163 | C19: -0.12493863 | D19: -0.5766037 | E19: 0.10881306 | F19: -0.54691452 | G19: -0.59719329 | H19: -0.51683368 | I19: -0.76797019 | J19: 0.42379 | K19: 0.18195674 | L19: -0.37298672 | M19: -0.18195674 | N19: 0.87099308

Sheet correlacao_ativos
A1: Coluna1 | B1: SMAQ | C1: Índice Bolsa EW (pontos) | D1: BANC | E1: LMAG | F1: DRWH | G1: SAUD | H1: PETN | I1: MM | J1: Renda Fixa - CP | K1: Renda Fixa - LP | L1: Dólar | M1: OURO10 | N1: Valor do Contrato Futuro em $ (Posição Comprada) | O1: Valor do Contrato Futuro em $ (Posição Vendida)
A2: SMAQ | B2: 1 | C2: 0.84210749 | D2: 0.77789364 | E2: 0.60509372 | F2: -0.021110788 | G2: 0.64974989 | H2: 0.75768878 | I2: 0.8531502 | J2: 0.31808153 | K2: -0.088403325 | L2: 0.7463102 | M2: 0.49477998 | N2: 0.35401403 | O2: -0.35401404
A3: MM | B3: 0.8531502 | C3: 0.90216911 | D3: 0.84172496 | E3: 0.71461246 | F3: 0.11225426 | G3: 0.83457196 | H3: 0.85491269 | I3: 1 | J3: 0.36411303 | K3: -0.13699395 | L3: 0.73564733 | M3: 0.63993578 | N3: 0.17889218 | O3: -0.17889218
A4: Índice Bolsa EW (pontos) | B4: 0.84210749 | C4: 1 | D4: 0.93076331 | E4: 0.8448105 | F4: 0.34475668 | G4: 0.78307306 | H4: 0.87560214 | I4: 0.90216911 | J4: 0.57007028 | K4: 0.11934329 | L4: 0.71370832 | M4: 0.79580352 | N4: 0.29437998 | O4: -0.29437998
A5: BANC | B5: 0.77789364 | C5: 0.93076331 | D5: 1 | E5: 0.70754629 | F5: 0.35276238 | G5: 0.71573957 | H5: 0.78645146 | I5: 0.84172496 | J5: 0.45749672 | K5: 0.1254736 | L5: 0.56034447 | M5: 0.78490548 | N5: 0.15011417 | O5: -0.15011417
A6: PETN | B6: 0.75768878 | C6: 0.87560214 | D6: 0.78645146 | E6: 0.8225585 | F6: 0.3382044 | G6: 0.61618897 | H6: 1 | I6: 0.85491269 | J6: 0.3997887 | K6: 0.054094488 | L6: 0.64523227 | M6: 0.70213007 | N6: 0.17822072 | O6: -0.17822072
A7: Dólar | B7: 0.7463102 | C7: 0.71370832 | D7: 0.56034447 | E7: 0.63742318 | F7: -0.080521303 | G7: 0.5844263 | H7: 0.64523227 | I7: 0.73564733 | J7: 0.39028075 | K7: 0.015130283 | L7: 1 | M7: 0.53083051 | N7: 0.75524823 | O7: -0.75524823
A8: SAUD | B8: 0.64974989 | C8: 0.78307306 | D8: 0.71573957 | E8: 0.625848 | F8: 0.23339883 | G8: 1 | H8: 0.61618897 | I8: 0.83457196 | J8: 0.37384306 | K8: -0.19093893 | L8: 0.5844263 | M8: 0.53492452 | N8: 0.040096709 | O8: -0.040096709
A9: LMAG | B9: 0.60509372 | C9: 0.8448105 | D9: 0.70754629 | E9: 1 | F9: 0.41795571 | G9: 0.625848 | H9: 0.8225585 | I9: 0.71461246 | J9: 0.56593167 | K9: 0.18467501 | L9: 0.63742318 | M9: 0.73086629 | N9: 0.33760312 | O9: -0.33760312
A10: OURO10 | B10: 0.49477998 | C10: 0.79580352 | D10: 0.78490548 | E10: 0.73086629 | F10: 0.49971521 | G10: 0.53492452 | H10: 0.70213007 | I10: 0.63993578 | J10: 0.45368925 | K10: 0.39084986 | L10: 0.53083051 | M10: 1 | N10: 0.2929039 | O10: -0.2929039
A11: Valor do Contrato Futuro em $ (Posição Comprada) | B11: 0.35401403 | C11: 0.29437998 | D11: 0.15011417 | E11: 0.33760312 | F11: -0.1826433 | G11: 0.040096709 | H11: 0.17822072 | I11: 0.17889218 | J11: 0.36302355 | K11: 0.2852811 | L11: 0.75524823 | M11: 0.2929039 | N11: 1 | O11: -1
A12: Renda Fixa - CP | B12: 0.31808153 | C12: 0.57007028 | D12: 0.45749672 | E12: 0.56593167 | F12: 0.20995722 | G12: 0.37384306 | H12: 0.3997887 | I12: 0.36411303 | J12: 1 | K12: 0.4869168 | L12: 0.39028075 | M12: 0.45368925 | N12: 0.36302355 | O12: -0.36302355
A13: DRWH | B13: -0.021110788 | C13: 0.34475668 | D13: 0.35276238 | E13: 0.41795571 | F13: 1 | G13: 0.23339883 | H13: 0.3382044 | I13: 0.11225426 | J13: 0.20995722 | K13: 0.2630202 | L13: -0.080521303 | M13: 0.49971521 | N13: -0.1826433 | O13: 0.1826433
... A15: Valor do Contrato Futuro em $ (Posição Vendida) | B15: -0.35401404 | C15: -0.29437998 | D15: -0.15011417 | E15: -0.33760312 | F15: 0.1826433 | G15: -0.040096709 | H15: -0.17822072 | I15: -0.17889218 | J15: -0.36302355 | K15: -0.2852811 | L15: -0.75524823 | M15: -0.2929039 | N15: -1 | O15: 1
